Workbook

Sheet Controle de reservas
A1: CONTROLE DE RESERVAS | ABA ÚNICA
A3: Digite os dados do reserva e o local da cobertura. Nos demais campos, escolha uma opção da lista.
A5: Data do painel: | B5: =TODAY() | E5: Filial do painel: | F5: Todas | H5: Painel diário abaixo. Consulte o calendário na aba Painel mensal; os lançamentos continuam somente nesta aba.
A7: Na reserva | C7: Em cobertura | E7: Disponíveis para alocar | G7: Não utilizados | I7: Sem registro na data | L7: Registros com pendência
A8: =SUM($R$14:$R$2013) | C8: =COUNTIFS($R$14:$R$2013,1,$K$14:$K$2013,$B$5,$L$14:$L$2013,"Em cobertura",$P$14:$P$2013,"OK") | E8: =COUNTIFS($R$14:$R$2013,1,$K$14:$K$2013,$B$5,$L$14:$L$2013,"Disponível",$P$14:$P$2013,"OK") | G8: =COUNTIFS($R$14:$R$2013,1,$K$14:$K$2013,$B$5,$L$14:$L$2013,"Não utilizado",$P$14:$P$2013,"OK") | I8: =COUNTIFS($R$14:$R$2013,1,$K$14:$K$2013,"<>"&$B$5) | L8: =COUNTIFS($K$14:$K$2013,$B$5,$P$14:$P$2013,"<>",$P$14:$P$2013,"<>OK",$C$14:$C$2013,IF($F$5="Todas","*",$F$5))
A10: HISTÓRICO: use 1 linha por reserva e dia. No novo dia, copie a linha anterior e altere Data, Situação, Local e Matrícula substituída. Preserve a linha antiga.
A11: DATAS: registro após a previsão de saída gera divergência. Informe a matrícula substituída quando houver; ela aparecerá abaixo do local no painel mensal.
A13: Matrícula | B13: Nome do colaborador | C13: Filial | D13: Função | E13: Escala | F13: Tipo de reserva | G13: Motivo da entrada | H13: Entrada na reserva | I13: Previsão de saída | J13: Saída efetiva | K13: Data do registro | L13: Situação do dia | M13: Local da cobertura | N13: Matrícula substituída | O13: Ação / conferência
O14: =IF(AND(ISNUMBER(I14),ISNUMBER(K14),K14>I14),IF(P14="OK","DIVERGÊNCIA NAS DATAS — REGISTRO APÓS PREVISÃO",IF(P14="","DIVERGÊNCIA NAS DATAS — REGISTRO APÓS PREVISÃO",P14&CHAR(10)&"DIVERGÊNCIA NAS DATAS")),IF(P14="","",IF(P14<>"OK",P14,IF(L14="Disponível","ALOCAR COBERTURA",IF(L14="Não utilizado","SEM TRABALHO — PRIORIZAR",IF(L14="Ocorrência","VERIFICAR OCORRÊNCIA",IF(L14="Programado","CONFIRMAR COBERTURA",IF(AND(I14<>"",I14<TODAY(),J14=""),"PREVISÃO DE SAÍDA VENCIDA","OK")))))))) | P14: =IF(COUNTA(A14:N14)=0,"",IF(OR(A14="",B14="",C14="",D14="",E14="",F14="",G14="",H14="",K14="",L14=""),"COMPLETE CAMPOS / SITUAÇÃO",IF(COUNTIFS($A$14:$A$2013,A14,$K$14:$K$2013,K14)>1,"DUPLICIDADE NO DIA",IF(OR(K14<H14,AND(J14<>"",K14>J14)),"DATA FORA DA RESERVA",IF(AND(J14<>"",J14<H14),"SAÍDA ANTES DA ENTRADA",IF(AND(I14<>"",I14<H14),"PREVISÃO ANTES DA ENTRADA",IF(AND(OR(L14="Em cobertura",L14="Programado"),M14=""),"INFORME LOCAL DA COBERTURA",IF(AND(K14>TODAY(),OR(L14="Em cobertura",L14="Não utilizado")),"DATA FUTURA: USE PROGRAMADO","OK")))))))) | Q14: =IF(OR(A14="",H14=""),"",A14&"|"&TEXT(H14,"yyyymmdd")) | R14: =IF(OR($Q14="",K14="",K14>$B$5,H14>$B$5,AND(J14<>"",J14<$B$5),AND($F$5<>"Todas",C14<>$F$5)),0,IF(AND(COUNTIFS($Q$14:$Q$2013,Q14,$K$14:$K$2013,">"&K14,$K$14:$K$2013,"<="&$B$5)=0,COUNTIFS($Q$14:Q14,Q14,$K$14:K14,K14)=1),1,0)) | S14: =IF(AND($Q14<>"",H14<>"",H14<=EOMONTH('Painel mensal'!$B$5,0),OR(J14="",J14>='Painel mensal'!$B$5),K14<>"",K14<=EOMONTH('Painel mensal'!$B$5,0),OR('Painel mensal'!$E$5="Todas",C14='Painel mensal'!$E$5),COUNTIFS($Q$14:$Q$2013,Q14,$K$14:$K$2013,">"&K14,$K$14:$K$2013,"<="&EOMONTH('Painel mensal'!$B$5,0))=0,COUNTIFS($Q$14:Q14,Q14,$K$14:K14,K14)=1),COUNT($S$13:S13)+1,"") | T14: =IF(OR(Q14="",K14=""),"",Q14&"|"&TEXT(K14,"yyyymmdd"))
O15: =IF(AND(ISNUMBER(I15),ISNUMBER(K15),K15>I15),IF(P15="OK","DIVERGÊNCIA NAS DATAS — REGISTRO APÓS PREVISÃO",IF(P15="","DIVERGÊNCIA NAS DATAS — REGISTRO APÓS PREVISÃO",P15&CHAR(10)&"DIVERGÊNCIA NAS DATAS")),IF(P15="","",IF(P15<>"OK",P15,IF(L15="Disponível","ALOCAR COBERTURA",IF(L15="Não utilizado","SEM TRABALHO — PRIORIZAR",IF(L15="Ocorrência","VERIFICAR OCORRÊNCIA",IF(L15="Programado","CONFIRMAR COBERTURA",IF(AND(I15<>"",I15<TODAY(),J15=""),"PREVISÃO DE SAÍDA VENCIDA","OK")))))))) | P15: =IF(COUNTA(A15:N15)=0,"",IF(OR(A15="",B15="",C15="",D15="",E15="",F15="",G15="",H15="",K15="",L15=""),"COMPLETE CAMPOS / SITUAÇÃO",IF(COUNTIFS($A$14:$A$2013,A15,$K$14:$K$2013,K15)>1,"DUPLICIDADE NO DIA",IF(OR(K15<H15,AND(J15<>"",K15>J15)),"DATA FORA DA RESERVA",IF(AND(J15<>"",J15<H15),"SAÍDA ANTES DA ENTRADA",IF(AND(I15<>"",I15<H15),"PREVISÃO ANTES DA ENTRADA",IF(AND(OR(L15="Em cobertura",L15="Programado"),M15=""),"INFORME LOCAL DA COBERTURA",IF(AND(K15>TODAY(),OR(L15="Em cobertura",L15="Não utilizado")),"DATA FUTURA: USE PROGRAMADO","OK")))))))) | Q15: =IF(OR(A15="",H15=""),"",A15&"|"&TEXT(H15,"yyyymmdd")) | R15: =IF(OR($Q15="",K15="",K15>$B$5,H15>$B$5,AND(J15<>"",J15<$B$5),AND($F$5<>"Todas",C15<>$F$5)),0,IF(AND(COUNTIFS($Q$14:$Q$2013,Q15,$K$14:$K$2013,">"&K15,$K$14:$K$2013,"<="&$B$5)=0,COUNTIFS($Q$14:Q15,Q15,$K$14:K15,K15)=1),1,0)) | S15: =IF(AND($Q15<>"",H15<>"",H15<=EOMONTH('Painel mensal'!$B$5,0),OR(J15="",J15>='Painel mensal'!$B$5),K15<>"",K15<=EOMONTH('Painel mensal'!$B$5,0),OR('Painel mensal'!$E$5="Todas",C15='Painel mensal'!$E$5),COUNTIFS($Q$14:$Q$2013,Q15,$K$14:$K$2013,">"&K15,$K$14:$K$2013,"<="&EOMONTH('Painel mensal'!$B$5,0))=0,COUNTIFS($Q$14:Q15,Q15,$K$14:K15,K15)=1),COUNT($S$13:S14)+1,"") | T15: =IF(OR(Q15="",K15=""),"",Q15&"|"&TEXT(K15,"yyyymmdd"))
O16: =IF(AND(ISNUMBER(I16),ISNUMBER(K16),K16>I16),IF(P16="OK","DIVERGÊNCIA NAS DATAS — REGISTRO APÓS PREVISÃO",IF(P16="","DIVERGÊNCIA NAS DATAS — REGISTRO APÓS PREVISÃO",P16&CHAR(10)&"DIVERGÊNCIA NAS DATAS")),IF(P16="","",IF(P16<>"OK",P16,IF(L16="Disponível","ALOCAR COBERTURA",IF(L16="Não utilizado","SEM TRABALHO — PRIORIZAR",IF(L16="Ocorrência","VERIFICAR OCORRÊNCIA",IF(L16="Programado","CONFIRMAR COBERTURA",IF(AND(I16<>"",I16<TODAY(),J16=""),"PREVISÃO DE SAÍDA VENCIDA","OK")))))))) | P16: =IF(COUNTA(A16:N16)=0,"",IF(OR(A16="",B16="",C16="",D16="",E16="",F16="",G16="",H16="",K16="",L16=""),"COMPLETE CAMPOS / SITUAÇÃO",IF(COUNTIFS($A$14:$A$2013,A16,$K$14:$K$2013,K16)>1,"DUPLICIDADE NO DIA",IF(OR(K16<H16,AND(J16<>"",K16>J16)),"DATA FORA DA RESERVA",IF(AND(J16<>"",J16<H16),"SAÍDA ANTES DA ENTRADA",IF(AND(I16<>"",I16<H16),"PREVISÃO ANTES DA ENTRADA",IF(AND(OR(L16="Em cobertura",L16="Programado"),M16=""),"INFORME LOCAL DA COBERTURA",IF(AND(K16>TODAY(),OR(L16="Em cobertura",L16="Não utilizado")),"DATA FUTURA: USE PROGRAMADO","OK")))))))) | Q16: =IF(OR(A16="",H16=""),"",A16&"|"&TEXT(H16,"yyyymmdd")) | R16: =IF(OR($Q16="",K16="",K16>$B$5,H16>$B$5,AND(J16<>"",J16<$B$5),AND($F$5<>"Todas",C16<>$F$5)),0,IF(AND(COUNTIFS($Q$14:$Q$2013,Q16,$K$14:$K$2013,">"&K16,$K$14:$K$2013,"<="&$B$5)=0,COUNTIFS($Q$14:Q16,Q16,$K$14:K16,K16)=1),1,0)) | S16: =IF(AND($Q16<>"",H16<>"",H16<=EOMONTH('Painel mensal'!$B$5,0),OR(J16="",J16>='Painel mensal'!$B$5),K16<>"",K16<=EOMONTH('Painel mensal'!$B$5,0),OR('Painel mensal'!$E$5="Todas",C16='Painel mensal'!$E$5),COUNTIFS($Q$14:$Q$2013,Q16,$K$14:$K$2013,">"&K16,$K$14:$K$2013,"<="&EOMONTH('Painel mensal'!$B$5,0))=0,COUNTIFS($Q$14:Q16,Q16,$K$14:K16,K16)=1),COUNT($S$13:S15)+1,"") | T16: =IF(OR(Q16="",K16=""),"",Q16&"|"&TEXT(K16,"yyyymmdd"))
O17: =IF(AND(ISNUMBER(I17),ISNUMBER(K17),K17>I17),IF(P17="OK","DIVERGÊNCIA NAS DATAS — REGISTRO APÓS PREVISÃO",IF(P17="","DIVERGÊNCIA NAS DATAS — REGISTRO APÓS PREVISÃO",P17&CHAR(10)&"DIVERGÊNCIA NAS DATAS")),IF(P17="","",IF(P17<>"OK",P17,IF(L17="Disponível","ALOCAR COBERTURA",IF(L17="Não utilizado","SEM TRABALHO — PRIORIZAR",IF(L17="Ocorrência","VERIFICAR OCORRÊNCIA",IF(L17="Programado","CONFIRMAR COBERTURA",IF(AND(I17<>"",I17<TODAY(),J17=""),"PREVISÃO DE SAÍDA VENCIDA","OK")))))))) | P17: =IF(COUNTA(A17:N17)=0,"",IF(OR(A17="",B17="",C17="",D17="",E17="",F17="",G17="",H17="",K17="",L17=""),"COMPLETE CAMPOS / SITUAÇÃO",IF(COUNTIFS($A$14:$A$2013,A17,$K$14:$K$2013,K17)>1,"DUPLICIDADE NO DIA",IF(OR(K17<H17,AND(J17<>"",K17>J17)),"DATA FORA DA RESERVA",IF(AND(J17<>"",J17<H17),"SAÍDA ANTES DA ENTRADA",IF(AND(I17<>"",I17<H17),"PREVISÃO ANTES DA ENTRADA",IF(AND(OR(L17="Em cobertura",L17="Programado"),M17=""),"INFORME LOCAL DA COBERTURA",IF(AND(K17>TODAY(),OR(L17="Em cobertura",L17="Não utilizado")),"DATA FUTURA: USE PROGRAMADO","OK")))))))) | Q17: =IF(OR(A17="",H17=""),"",A17&"|"&TEXT(H17,"yyyymmdd")) | R17: =IF(OR($Q17="",K17="",K17>$B$5,H17>$B$5,AND(J17<>"",J17<$B$5),AND($F$5<>"Todas",C17<>$F$5)),0,IF(AND(COUNTIFS($Q$14:$Q$2013,Q17,$K$14:$K$2013,">"&K17,$K$14:$K$2013,"<="&$B$5)=0,COUNTIFS($Q$14:Q17,Q17,$K$14:K17,K17)=1),1,0)) | S17: =IF(AND($Q17<>"",H17<>"",H17<=EOMONTH('Painel mensal'!$B$5,0),OR(J17="",J17>='Painel mensal'!$B$5),K17<>"",K17<=EOMONTH('Painel mensal'!$B$5,0),OR('Painel mensal'!$E$5="Todas",C17='Painel mensal'!$E$5),COUNTIFS($Q$14:$Q$2013,Q17,$K$14:$K$2013,">"&K17,$K$14:$K$2013,"<="&EOMONTH('Painel mensal'!$B$5,0))=0,COUNTIFS($Q$14:Q17,Q17,$K$14:K17,K17)=1),COUNT($S$13:S16)+1,"") | T17: =IF(OR(Q17="",K17=""),"",Q17&"|"&TEXT(K17,"yyyymmdd"))
O18: =IF(AND(ISNUMBER(I18),ISNUMBER(K18),K18>I18),IF(P18="OK","DIVERGÊNCIA NAS DATAS — REGISTRO APÓS PREVISÃO",IF(P18="","DIVERGÊNCIA NAS DATAS — REGISTRO APÓS PREVISÃO",P18&CHAR(10)&"DIVERGÊNCIA NAS DATAS")),IF(P18="","",IF(P18<>"OK",P18,IF(L18="Disponível","ALOCAR COBERTURA",IF(L18="Não utilizado","SEM TRABALHO — PRIORIZAR",IF(L18="Ocorrência","VERIFICAR OCORRÊNCIA",IF(L18="Programado","CONFIRMAR COBERTURA",IF(AND(I18<>"",I18<TODAY(),J18=""),"PREVISÃO DE SAÍDA VENCIDA","OK")))))))) | P18: =IF(COUNTA(A18:N18)=0,"",IF(OR(A18="",B18="",C18="",D18="",E18="",F18="",G18="",H18="",K18="",L18=""),"COMPLETE CAMPOS / SITUAÇÃO",IF(COUNTIFS($A$14:$A$2013,A18,$K$14:$K$2013,K18)>1,"DUPLICIDADE NO DIA",IF(OR(K18<H18,AND(J18<>"",K18>J18)),"DATA FORA DA RESERVA",IF(AND(J18<>"",J18<H18),"SAÍDA ANTES DA ENTRADA",IF(AND(I18<>"",I18<H18),"PREVISÃO ANTES DA ENTRADA",IF(AND(OR(L18="Em cobertura",L18="Programado"),M18=""),"INFORME LOCAL DA COBERTURA",IF(AND(K18>TODAY(),OR(L18="Em cobertura",L18="Não utilizado")),"DATA FUTURA: USE PROGRAMADO","OK")))))))) | Q18: =IF(OR(A18="",H18=""),"",A18&"|"&TEXT(H18,"yyyymmdd")) | R18: =IF(OR($Q18="",K18="",K18>$B$5,H18>$B$5,AND(J18<>"",J18<$B$5),AND($F$5<>"Todas",C18<>$F$5)),0,IF(AND(COUNTIFS($Q$14:$Q$2013,Q18,$K$14:$K$2013,">"&K18,$K$14:$K$2013,"<="&$B$5)=0,COUNTIFS($Q$14:Q18,Q18,$K$14:K18,K18)=1),1,0)) | S18: =IF(AND($Q18<>"",H18<>"",H18<=EOMONTH('Painel mensal'!$B$5,0),OR(J18="",J18>='Painel mensal'!$B$5),K18<>"",K18<=EOMONTH('Painel mensal'!$B$5,0),OR('Painel mensal'!$E$5="Todas",C18='Painel mensal'!$E$5),COUNTIFS($Q$14:$Q$2013,Q18,$K$14:$K$2013,">"&K18,$K$14:$K$2013,"<="&EOMONTH('Painel mensal'!$B$5,0))=0,COUNTIFS($Q$14:Q18,Q18,$K$14:K18,K18)=1),COUNT($S$13:S17)+1,"") | T18: =IF(OR(Q18="",K18=""),"",Q18&"|"&TEXT(K18,"yyyymmdd"))
O19: =IF(AND(ISNUMBER(I19),ISNUMBER(K19),K19>I19),IF(P19="OK","DIVERGÊNCIA NAS DATAS — REGISTRO APÓS PREVISÃO",IF(P19="","DIVERGÊNCIA NAS DATAS — REGISTRO APÓS PREVISÃO",P19&CHAR(10)&"DIVERGÊNCIA NAS DATAS")),IF(P19="","",IF(P19<>"OK",P19,IF(L19="Disponível","ALOCAR COBERTURA",IF(L19="Não utilizado","SEM TRABALHO — PRIORIZAR",IF(L19="Ocorrência","VERIFICAR OCORRÊNCIA",IF(L19="Programado","CONFIRMAR COBERTURA",IF(AND(I19<>"",I19<TODAY(),J19=""),"PREVISÃO DE SAÍDA VENCIDA","OK")))))))) | P19: =IF(COUNTA(A19:N19)=0,"",IF(OR(A19="",B19="",C19="",D19="",E19="",F19="",G19="",H19="",K19="",L19=""),"COMPLETE CAMPOS / SITUAÇÃO",IF(COUNTIFS($A$14:$A$2013,A19,$K$14:$K$2013,K19)>1,"DUPLICIDADE NO DIA",IF(OR(K19<H19,AND(J19<>"",K19>J19)),"DATA FORA DA RESERVA",IF(AND(J19<>"",J19<H19),"SAÍDA ANTES DA ENTRADA",IF(AND(I19<>"",I19<H19),"PREVISÃO ANTES DA ENTRADA",IF(AND(OR(L19="Em cobertura",L19="Programado"),M19=""),"INFORME LOCAL DA COBERTURA",IF(AND(K19>TODAY(),OR(L19="Em cobertura",L19="Não utilizado")),"DATA FUTURA: USE PROGRAMADO","OK")))))))) | Q19: =IF(OR(A19="",H19=""),"",A19&"|"&TEXT(H19,"yyyymmdd")) | R19: =IF(OR($Q19="",K19="",K19>$B$5,H19>$B$5,AND(J19<>"",J19<$B$5),AND($F$5<>"Todas",C19<>$F$5)),0,IF(AND(COUNTIFS($Q$14:$Q$2013,Q19,$K$14:$K$2013,">"&K19,$K$14:$K$2013,"<="&$B$5)=0,COUNTIFS($Q$14:Q19,Q19,$K$14:K19,K19)=1),1,0)) | S19: =IF(AND($Q19<>"",H19<>"",H19<=EOMONTH('Painel mensal'!$B$5,0),OR(J19="",J19>='Painel mensal'!$B$5),K19<>"",K19<=EOMONTH('Painel mensal'!$B$5,0),OR('Painel mensal'!$E$5="Todas",C19='Painel mensal'!$E$5),COUNTIFS($Q$14:$Q$2013,Q19,$K$14:$K$2013,">"&K19,$K$14:$K$2013,"<="&EOMONTH('Painel mensal'!$B$5,0))=0,COUNTIFS($Q$14:Q19,Q19,$K$14:K19,K19)=1),COUNT($S$13:S18)+1,"") | T19: =IF(OR(Q19="",K19=""),"",Q19&"|"&TEXT(K19,"yyyymmdd"))
O20: =IF(AND(ISNUMBER(I20),ISNUMBER(K20),K20>I20),IF(P20="OK","DIVERGÊNCIA NAS DATAS — REGISTRO APÓS PREVISÃO",IF(P20="","DIVERGÊNCIA NAS DATAS — REGISTRO APÓS PREVISÃO",P20&CHAR(10)&"DIVERGÊNCIA NAS DATAS")),IF(P20="","",IF(P20<>"OK",P20,IF(L20="Disponível","ALOCAR COBERTURA",IF(L20="Não utilizado","SEM TRABALHO — PRIORIZAR",IF(L20="Ocorrência","VERIFICAR OCORRÊNCIA",IF(L20="Programado","CONFIRMAR COBERTURA",IF(AND(I20<>"",I20<TODAY(),J20=""),"PREVISÃO DE SAÍDA VENCIDA","OK")))))))) | P20: =IF(COUNTA(A20:N20)=0,"",IF(OR(A20="",B20="",C20="",D20="",E20="",F20="",G20="",H20="",K20="",L20=""),"COMPLETE CAMPOS / SITUAÇÃO",IF(COUNTIFS($A$14:$A$2013,A20,$K$14:$K$2013,K20)>1,"DUPLICIDADE NO DIA",IF(OR(K20<H20,AND(J20<>"",K20>J20)),"DATA FORA DA RESERVA",IF(AND(J20<>"",J20<H20),"SAÍDA ANTES DA ENTRADA",IF(AND(I20<>"",I20<H20),"PREVISÃO ANTES DA ENTRADA",IF(AND(OR(L20="Em cobertura",L20="Programado"),M20=""),"INFORME LOCAL DA COBERTURA",IF(AND(K20>TODAY(),OR(L20="Em cobertura",L20="Não utilizado")),"DATA FUTURA: USE PROGRAMADO","OK")))))))) | Q20: =IF(OR(A20="",H20=""),"",A20&"|"&TEXT(H20,"yyyymmdd")) | R20: =IF(OR($Q20="",K20="",K20>$B$5,H20>$B$5,AND(J20<>"",J20<$B$5),AND($F$5<>"Todas",C20<>$F$5)),0,IF(AND(COUNTIFS($Q$14:$Q$2013,Q20,$K$14:$K$2013,">"&K20,$K$14:$K$2013,"<="&$B$5)=0,COUNTIFS($Q$14:Q20,Q20,$K$14:K20,K20)=1),1,0)) | S20: =IF(AND($Q20<>"",H20<>"",H20<=EOMONTH('Painel mensal'!$B$5,0),OR(J20="",J20>='Painel mensal'!$B$5),K20<>"",K20<=EOMONTH('Painel mensal'!$B$5,0),OR('Painel mensal'!$E$5="Todas",C20='Painel mensal'!$E$5),COUNTIFS($Q$14:$Q$2013,Q20,$K$14:$K$2013,">"&K20,$K$14:$K$2013,"<="&EOMONTH('Painel mensal'!$B$5,0))=0,COUNTIFS($Q$14:Q20,Q20,$K$14:K20,K20)=1),COUNT($S$13:S19)+1,"") | T20: =IF(OR(Q20="",K20=""),"",Q20&"|"&TEXT(K20,"yyyymmdd"))
O21: =IF(AND(ISNUMBER(I21),ISNUMBER(K21),K21>I21),IF(P21="OK","DIVERGÊNCIA NAS DATAS — REGISTRO APÓS PREVISÃO",IF(P21="","DIVERGÊNCIA NAS DATAS — REGISTRO APÓS PREVISÃO",P21&CHAR(10)&"DIVERGÊNCIA NAS DATAS")),IF(P21="","",IF(P21<>"OK",P21,IF(L21="Disponível","ALOCAR COBERTURA",IF(L21="Não utilizado","SEM TRABALHO — PRIORIZAR",IF(L21="Ocorrência","VERIFICAR OCORRÊNCIA",IF(L21="Programado","CONFIRMAR COBERTURA",IF(AND(I21<>"",I21<TODAY(),J21=""),"PREVISÃO DE SAÍDA VENCIDA","OK")))))))) | P21: =IF(COUNTA(A21:N21)=0,"",IF(OR(A21="",B21="",C21="",D21="",E21="",F21="",G21="",H21="",K21="",L21=""),"COMPLETE CAMPOS / SITUAÇÃO",IF(COUNTIFS($A$14:$A$2013,A21,$K$14:$K$2013,K21)>1,"DUPLICIDADE NO DIA",IF(OR(K21<H21,AND(J21<>"",K21>J21)),"DATA FORA DA RESERVA",IF(AND(J21<>"",J21<H21),"SAÍDA ANTES DA ENTRADA",IF(AND(I21<>"",I21<H21),"PREVISÃO ANTES DA ENTRADA",IF(AND(OR(L21="Em cobertura",L21="Programado"),M21=""),"INFORME LOCAL DA COBERTURA",IF(AND(K21>TODAY(),OR(L21="Em cobertura",L21="Não utilizado")),"DATA FUTURA: USE PROGRAMADO","OK")))))))) | Q21: =IF(OR(A21="",H21=""),"",A21&"|"&TEXT(H21,"yyyymmdd")) | R21: =IF(OR($Q21="",K21="",K21>$B$5,H21>$B$5,AND(J21<>"",J21<$B$5),AND($F$5<>"Todas",C21<>$F$5)),0,IF(AND(COUNTIFS($Q$14:$Q$2013,Q21,$K$14:$K$2013,">"&K21,$K$14:$K$2013,"<="&$B$5)=0,COUNTIFS($Q$14:Q21,Q21,$K$14:K21,K21)=1),1,0)) | S21: =IF(AND($Q21<>"",H21<>"",H21<=EOMONTH('Painel mensal'!$B$5,0),OR(J21="",J21>='Painel mensal'!$B$5),K21<>"",K21<=EOMONTH('Painel mensal'!$B$5,0),OR('Painel mensal'!$E$5="Todas",C21='Painel mensal'!$E$5),COUNTIFS($Q$14:$Q$2013,Q21,$K$14:$K$2013,">"&K21,$K$14:$K$2013,"<="&EOMONTH('Painel mensal'!$B$5,0))=0,COUNTIFS($Q$14:Q21,Q21,$K$14:K21,K21)=1),COUNT($S$13:S20)+1,"") | T21: =IF(OR(Q21="",K21=""),"",Q21&"|"&TEXT(K21,"yyyymmdd"))
O22: =IF(AND(ISNUMBER(I22),ISNUMBER(K22),K22>I22),IF(P22="OK","DIVERGÊNCIA NAS DATAS — REGISTRO APÓS PREVISÃO",IF(P22="","DIVERGÊNCIA NAS DATAS — REGISTRO APÓS PREVISÃO",P22&CHAR(10)&"DIVERGÊNCIA NAS DATAS")),IF(P22="","",IF(P22<>"OK",P22,IF(L22="Disponível","ALOCAR COBERTURA",IF(L22="Não utilizado","SEM TRABALHO — PRIORIZAR",IF(L22="Ocorrência","VERIFICAR OCORRÊNCIA",IF(L22="Programado","CONFIRMAR COBERTURA",IF(AND(I22<>"",I22<TODAY(),J22=""),"PREVISÃO DE SAÍDA VENCIDA","OK")))))))) | P22: =IF(COUNTA(A22:N22)=0,"",IF(OR(A22="",B22="",C22="",D22="",E22="",F22="",G22="",H22="",K22="",L22=""),"COMPLETE CAMPOS / SITUAÇÃO",IF(COUNTIFS($A$14:$A$2013,A22,$K$14:$K$2013,K22)>1,"DUPLICIDADE NO DIA",IF(OR(K22<H22,AND(J22<>"",K22>J22)),"DATA FORA DA RESERVA",IF(AND(J22<>"",J22<H22),"SAÍDA ANTES DA ENTRADA",IF(AND(I22<>"",I22<H22),"PREVISÃO ANTES DA ENTRADA",IF(AND(OR(L22="Em cobertura",L22="Programado"),M22=""),"INFORME LOCAL DA COBERTURA",IF(AND(K22>TODAY(),OR(L22="Em cobertura",L22="Não utilizado")),"DATA FUTURA: USE PROGRAMADO","OK")))))))) | Q22: =IF(OR(A22="",H22=""),"",A22&"|"&TEXT(H22,"yyyymmdd")) | R22: =IF(OR($Q22="",K22="",K22>$B$5,H22>$B$5,AND(J22<>"",J22<$B$5),AND($F$5<>"Todas",C22<>$F$5)),0,IF(AND(COUNTIFS($Q$14:$Q$2013,Q22,$K$14:$K$2013,">"&K22,$K$14:$K$2013,"<="&$B$5)=0,COUNTIFS($Q$14:Q22,Q22,$K$14:K22,K22)=1),1,0)) | S22: =IF(AND($Q22<>"",H22<>"",H22<=EOMONTH('Painel mensal'!$B$5,0),OR(J22="",J22>='Painel mensal'!$B$5),K22<>"",K22<=EOMONTH('Painel mensal'!$B$5,0),OR('Painel mensal'!$E$5="Todas",C22='Painel mensal'!$E$5),COUNTIFS($Q$14:$Q$2013,Q22,$K$14:$K$2013,">"&K22,$K$14:$K$2013,"<="&EOMONTH('Painel mensal'!$B$5,0))=0,COUNTIFS($Q$14:Q22,Q22,$K$14:K22,K22)=1),COUNT($S$13:S21)+1,"") | T22: =IF(OR(Q22="",K22=""),"",Q22&"|"&TEXT(K22,"yyyymmdd"))
O23: =IF(AND(ISNUMBER(I23),ISNUMBER(K23),K23>I23),IF(P23="OK","DIVERGÊNCIA NAS DATAS — REGISTRO APÓS PREVISÃO",IF(P23="","DIVERGÊNCIA NAS DATAS — REGISTRO APÓS PREVISÃO",P23&CHAR(10)&"DIVERGÊNCIA NAS DATAS")),IF(P23="","",IF(P23<>"OK",P23,IF(L23="Disponível","ALOCAR COBERTURA",IF(L23="Não utilizado","SEM TRABALHO — PRIORIZAR",IF(L23="Ocorrência","VERIFICAR OCORRÊNCIA",IF(L23="Programado","CONFIRMAR COBERTURA",IF(AND(I23<>"",I23<TODAY(),J23=""),"PREVISÃO DE SAÍDA VENCIDA","OK")))))))) | P23: =IF(COUNTA(A23:N23)=0,"",IF(OR(A23="",B23="",C23="",D23="",E23="",F23="",G23="",H23="",K23="",L23=""),"COMPLETE CAMPOS / SITUAÇÃO",IF(COUNTIFS($A$14:$A$2013,A23,$K$14:$K$2013,K23)>1,"DUPLICIDADE NO DIA",IF(OR(K23<H23,AND(J23<>"",K23>J23)),"DATA FORA DA RESERVA",IF(AND(J23<>"",J23<H23),"SAÍDA ANTES DA ENTRADA",IF(AND(I23<>"",I23<H23),"PREVISÃO ANTES DA ENTRADA",IF(AND(OR(L23="Em cobertura",L23="Programado"),M23=""),"INFORME LOCAL DA COBERTURA",IF(AND(K23>TODAY(),OR(L23="Em cobertura",L23="Não utilizado")),"DATA FUTURA: USE PROGRAMADO","OK")))))))) | Q23: =IF(OR(A23="",H23=""),"",A23&"|"&TEXT(H23,"yyyymmdd")) | R23: =IF(OR($Q23="",K23="",K23>$B$5,H23>$B$5,AND(J23<>"",J23<$B$5),AND($F$5<>"Todas",C23<>$F$5)),0,IF(AND(COUNTIFS($Q$14:$Q$2013,Q23,$K$14:$K$2013,">"&K23,$K$14:$K$2013,"<="&$B$5)=0,COUNTIFS($Q$14:Q23,Q23,$K$14:K23,K23)=1),1,0)) | S23: =IF(AND($Q23<>"",H23<>"",H23<=EOMONTH('Painel mensal'!$B$5,0),OR(J23="",J23>='Painel mensal'!$B$5),K23<>"",K23<=EOMONTH('Painel mensal'!$B$5,0),OR('Painel mensal'!$E$5="Todas",C23='Painel mensal'!$E$5),COUNTIFS($Q$14:$Q$2013,Q23,$K$14:$K$2013,">"&K23,$K$14:$K$2013,"<="&EOMONTH('Painel mensal'!$B$5,0))=0,COUNTIFS($Q$14:Q23,Q23,$K$14:K23,K23)=1),COUNT($S$13:S22)+1,"") | T23: =IF(OR(Q23="",K23=""),"",Q23&"|"&TEXT(K23,"yyyymmdd"))
O24: =IF(AND(ISNUMBER(I24),ISNUMBER(K24),K24>I24),IF(P24="OK","DIVERGÊNCIA NAS DATAS — REGISTRO APÓS PREVISÃO",IF(P24="","DIVERGÊNCIA NAS DATAS — REGISTRO APÓS PREVISÃO",P24&CHAR(10)&"DIVERGÊNCIA NAS DATAS")),IF(P24="","",IF(P24<>"OK",P24,IF(L24="Disponível","ALOCAR COBERTURA",IF(L24="Não utilizado","SEM TRABALHO — PRIORIZAR",IF(L24="Ocorrência","VERIFICAR OCORRÊNCIA",IF(L24="Programado","CONFIRMAR COBERTURA",IF(AND(I24<>"",I24<TODAY(),J24=""),"PREVISÃO DE SAÍDA VENCIDA","OK")))))))) | P24: =IF(COUNTA(A24:N24)=0,"",IF(OR(A24="",B24="",C24="",D24="",E24="",F24="",G24="",H24="",K24="",L24=""),"COMPLETE CAMPOS / SITUAÇÃO",IF(COUNTIFS($A$14:$A$2013,A24,$K$14:$K$2013,K24)>1,"DUPLICIDADE NO DIA",IF(OR(K24<H24,AND(J24<>"",K24>J24)),"DATA FORA DA RESERVA",IF(AND(J24<>"",J24<H24),"SAÍDA ANTES DA ENTRADA",IF(AND(I24<>"",I24<H24),"PREVISÃO ANTES DA ENTRADA",IF(AND(OR(L24="Em cobertura",L24="Programado"),M24=""),"INFORME LOCAL DA COBERTURA",IF(AND(K24>TODAY(),OR(L24="Em cobertura",L24="Não utilizado")),"DATA FUTURA: USE PROGRAMADO","OK")))))))) | Q24: =IF(OR(A24="",H24=""),"",A24&"|"&TEXT(H24,"yyyymmdd")) | R24: =IF(OR($Q24="",K24="",K24>$B$5,H24>$B$5,AND(J24<>"",J24<$B$5),AND($F$5<>"Todas",C24<>$F$5)),0,IF(AND(COUNTIFS($Q$14:$Q$2013,Q24,$K$14:$K$2013,">"&K24,$K$14:$K$2013,"<="&$B$5)=0,COUNTIFS($Q$14:Q24,Q24,$K$14:K24,K24)=1),1,0)) | S24: =IF(AND($Q24<>"",H24<>"",H24<=EOMONTH('Painel mensal'!$B$5,0),OR(J24="",J24>='Painel mensal'!$B$5),K24<>"",K24<=EOMONTH('Painel mensal'!$B$5,0),OR('Painel mensal'!$E$5="Todas",C24='Painel mensal'!$E$5),COUNTIFS($Q$14:$Q$2013,Q24,$K$14:$K$2013,">"&K24,$K$14:$K$2013,"<="&EOMONTH('Painel mensal'!$B$5,0))=0,COUNTIFS($Q$14:Q24,Q24,$K$14:K24,K24)=1),COUNT($S$13:S23)+1,"") | T24: =IF(OR(Q24="",K24=""),"",Q24&"|"&TEXT(K24,"yyyymmdd"))
O25: =IF(AND(ISNUMBER(I25),ISNUMBER(K25),K25>I25),IF(P25="OK","DIVERGÊNCIA NAS DATAS — REGISTRO APÓS PREVISÃO",IF(P25="","DIVERGÊNCIA NAS DATAS — REGISTRO APÓS PREVISÃO",P25&CHAR(10)&"DIVERGÊNCIA NAS DATAS")),IF(P25="","",IF(P25<>"OK",P25,IF(L25="Disponível","ALOCAR COBERTURA",IF(L25="Não utilizado","SEM TRABALHO — PRIORIZAR",IF(L25="Ocorrência","VERIFICAR OCORRÊNCIA",IF(L25="Programado","CONFIRMAR COBERTURA",IF(AND(I25<>"",I25<TODAY(),J25=""),"PREVISÃO DE SAÍDA VENCIDA","OK")))))))) | P25: =IF(COUNTA(A25:N25)=0,"",IF(OR(A25="",B25="",C25="",D25="",E25="",F25="",G25="",H25="",K25="",L25=""),"COMPLETE CAMPOS / SITUAÇÃO",IF(COUNTIFS($A$14:$A$2013,A25,$K$14:$K$2013,K25)>1,"DUPLICIDADE NO DIA",IF(OR(K25<H25,AND(J25<>"",K25>J25)),"DATA FORA DA RESERVA",IF(AND(J25<>"",J25<H25),"SAÍDA ANTES DA ENTRADA",IF(AND(I25<>"",I25<H25),"PREVISÃO ANTES DA ENTRADA",IF(AND(OR(L25="Em cobertura",L25="Programado"),M25=""),"INFORME LOCAL DA COBERTURA",IF(AND(K25>TODAY(),OR(L25="Em cobertura",L25="Não utilizado")),"DATA FUTURA: USE PROGRAMADO","OK")))))))) | Q25: =IF(OR(A25="",H25=""),"",A25&"|"&TEXT(H25,"yyyymmdd")) | R25: =IF(OR($Q25="",K25="",K25>$B$5,H25>$B$5,AND(J25<>"",J25<$B$5),AND($F$5<>"Todas",C25<>$F$5)),0,IF(AND(COUNTIFS($Q$14:$Q$2013,Q25,$K$14:$K$2013,">"&K25,$K$14:$K$2013,"<="&$B$5)=0,COUNTIFS($Q$14:Q25,Q25,$K$14:K25,K25)=1),1,0)) | S25: =IF(AND($Q25<>"",H25<>"",H25<=EOMONTH('Painel mensal'!$B$5,0),OR(J25="",J25>='Painel mensal'!$B$5),K25<>"",K25<=EOMONTH('Painel mensal'!$B$5,0),OR('Painel mensal'!$E$5="Todas",C25='Painel mensal'!$E$5),COUNTIFS($Q$14:$Q$2013,Q25,$K$14:$K$2013,">"&K25,$K$14:$K$2013,"<="&EOMONTH('Painel mensal'!$B$5,0))=0,COUNTIFS($Q$14:Q25,Q25,$K$14:K25,K25)=1),COUNT($S$13:S24)+1,"") | T25: =IF(OR(Q25="",K25=""),"",Q25&"|"&TEXT(K25,"yyyymmdd"))
... O2013: =IF(AND(ISNUMBER(I2013),ISNUMBER(K2013),K2013>I2013),IF(P2013="OK","DIVERGÊNCIA NAS DATAS — REGISTRO APÓS PREVISÃO",IF(P2013="","DIVERGÊNCIA NAS DATAS — REGISTRO APÓS PREVISÃO",P2013&CHAR(10)&"DIVERGÊNCIA NAS DATAS")),IF(P2013="","",IF(P2013<>"OK",P2013,IF(L2013="Disponível","ALOCAR COBERTURA",IF(L2013="Não utilizado","SEM TRABALHO — PRIORIZAR",IF(L2013="Ocorrência","VERIFICAR OCORRÊNCIA",IF(L2013="Programado","CONFIRMAR COBERTURA",IF(AND(I2013<>"",I2013<TODAY(),J2013=""),"PREVISÃO DE SAÍDA VENCIDA","OK")))))))) | P2013: =IF(COUNTA(A2013:N2013)=0,"",IF(OR(A2013="",B2013="",C2013="",D2013="",E2013="",F2013="",G2013="",H2013="",K2013="",L2013=""),"COMPLETE CAMPOS / SITUAÇÃO",IF(COUNTIFS($A$14:$A$2013,A2013,$K$14:$K$2013,K2013)>1,"DUPLICIDADE NO DIA",IF(OR(K2013<H2013,AND(J2013<>"",K2013>J2013)),"DATA FORA DA RESERVA",IF(AND(J2013<>"",J2013<H2013),"SAÍDA ANTES DA ENTRADA",IF(AND(I2013<>"",I2013<H2013),"PREVISÃO ANTES DA ENTRADA",IF(AND(OR(L2013="Em cobertura",L2013="Programado"),M2013=""),"INFORME LOCAL DA COBERTURA",IF(AND(K2013>TODAY(),OR(L2013="Em cobertura",L2013="Não utilizado")),"DATA FUTURA: USE PROGRAMADO","OK")))))))) | Q2013: =IF(OR(A2013="",H2013=""),"",A2013&"|"&TEXT(H2013,"yyyymmdd")) | R2013: =IF(OR($Q2013="",K2013="",K2013>$B$5,H2013>$B$5,AND(J2013<>"",J2013<$B$5),AND($F$5<>"Todas",C2013<>$F$5)),0,IF(AND(COUNTIFS($Q$14:$Q$2013,Q2013,$K$14:$K$2013,">"&K2013,$K$14:$K$2013,"<="&$B$5)=0,COUNTIFS($Q$14:Q2013,Q2013,$K$14:K2013,K2013)=1),1,0)) | S2013: =IF(AND($Q2013<>"",H2013<>"",H2013<=EOMONTH('Painel mensal'!$B$5,0),OR(J2013="",J2013>='Painel mensal'!$B$5),K2013<>"",K2013<=EOMONTH('Painel mensal'!$B$5,0),OR('Painel mensal'!$E$5="Todas",C2013='Painel mensal'!$E$5),COUNTIFS($Q$14:$Q$2013,Q2013,$K$14:$K$2013,">"&K2013,$K$14:$K$2013,"<="&EOMONTH('Painel mensal'!$B$5,0))=0,COUNTIFS($Q$14:Q2013,Q2013,$K$14:K2013,K2013)=1),COUNT($S$13:S2012)+1,"") | T2013: =IF(OR(Q2013="",K2013=""),"",Q2013&"|"&TEXT(K2013,"yyyymmdd"))

Sheet Painel mensal
A1: PAINEL MENSAL | ESCALA DOS RESERVAS
A3: Visualização automática no estilo do print: colaborador por linha, dias do mês lado a lado, situação e local.
A5: Mês (dia 01): | B5: =DATE(YEAR(TODAY()),MONTH(TODAY()),1) | D5: Filial: | E5: Todas | G5: Voltar ao preenchimento | L5: =IF(COUNT('Controle de reservas'!$S$14:$S$2013)>300,"AMPLIE O PAINEL: MAIS DE 300 PERÍODOS","Até 300 períodos por mês")
A7: COV = Em cobertura | DISP = Disponível | NU = Não utilizado | F = Folga | O = Ocorrência | PROG = Programado | DP = Disponível no posto
A8: Local na 2ª linha | Subst.: matrícula da pessoa substituída na linha abaixo | Registro após previsão: DIVERGÊNCIA DE DATAS | — = sem lançamento | ! = conferir dados
A9: Matrícula | B9: Colaborador | C9: Filial | D9: Função | E9: Escala | F9: Tipo reserva | G9: =IF(MONTH($B$5+COLUMN()-7)=MONTH($B$5),$B$5+COLUMN()-7,"") | H9: =IF(MONTH($B$5+COLUMN()-7)=MONTH($B$5),$B$5+COLUMN()-7,"") | I9: =IF(MONTH($B$5+COLUMN()-7)=MONTH($B$5),$B$5+COLUMN()-7,"") | J9: =IF(MONTH($B$5+COLUMN()-7)=MONTH($B$5),$B$5+COLUMN()-7,"") | K9: =IF(MONTH($B$5+COLUMN()-7)=MONTH($B$5),$B$5+COLUMN()-7,"") | L9: =IF(MONTH($B$5+COLUMN()-7)=MONTH($B$5),$B$5+COLUMN()-7,"") | M9: =IF(MONTH($B$5+COLUMN()-7)=MONTH($B$5),$B$5+COLUMN()-7,"") | N9: =IF(MONTH($B$5+COLUMN()-7)=MONTH($B$5),$B$5+COLUMN()-7,"") | ... AK9: =IF(MONTH($B$5+COLUMN()-7)=MONTH($B$5),$B$5+COLUMN()-7,"") | AL9: Dias COV | AM9: Dias DISP | AN9: Dias NU | AO9: Dias sem registro | AP9: Conferência
A10: =IF($AQ10=0,"",INDEX('Controle de reservas'!$A$14:$A$2013,$AQ10)) | B10: =IF($AQ10=0,"",INDEX('Controle de reservas'!$B$14:$B$2013,$AQ10)) | C10: =IF($AQ10=0,"",INDEX('Controle de reservas'!$C$14:$C$2013,$AQ10)) | D10: =IF($AQ10=0,"",INDEX('Controle de reservas'!$D$14:$D$2013,$AQ10)) | E10: =IF($AQ10=0,"",INDEX('Controle de reservas'!$E$14:$E$2013,$AQ10)) | F10: =IF($AQ10=0,"",INDEX('Controle de reservas'!$F$14:$F$2013,$AQ10)) | G10: =IF(OR($AQ10=0,G$9="",G$9<$AS10,AND($AT10<>"",G$9>$AT10)),"",IF(AU10=0,"—",IF(INDEX('Controle de reservas'!$P$14:$P$2013,AU10)="DUPLICIDADE NO DIA","CONFLITO"&IF(INDEX('Controle de reservas'!$M$14:$M$2013,AU10)<>"",CHAR(10)&INDEX('Controle de reservas'!$M$14:$M$2013,AU10),"")&IF(INDEX('Controle de reservas'!$N$14:$N$2013,AU10)<>"",CHAR(10)&"Subst.: "&INDEX('Controle de reservas'!$N$14:$N$2013,AU10),"")&IF(AND(ISNUMBER(INDEX('Controle de reservas'!$I$14:$I$2013,AU10)),INDEX('Controle de reservas'!$I$14:$I$2013,AU10)>0,INDEX('Controle de reservas'!$K$14:$K$2013,AU10)>INDEX('Controle de reservas'!$I$14:$I$2013,AU10)),CHAR(10)&"DIVERGÊNCIA DE DATAS",""),IF(INDEX('Controle de reservas'!$L$14:$L$2013,AU10)="Em cobertura","COV",IF(INDEX('Controle de reservas'!$L$14:$L$2013,AU10)="Disponível","DISP",IF(INDEX('Controle de reservas'!$L$14:$L$2013,AU10)="Não utilizado","NU",IF(INDEX('Controle de reservas'!$L$14:$L$2013,AU10)="Folga","F",IF(INDEX('Controle de reservas'!$L$14:$L$2013,AU10)="Ocorrência","O",IF(INDEX('Controle de reservas'!$L$14:$L$2013,AU10)="Programado","PROG",IF(INDEX('Controle de reservas'!$L$14:$L$2013,AU10)="Disponível no posto","DP","SEM SITUAÇÃO")))))))&IF(INDEX('Controle de reservas'!$M$14:$M$2013,AU10)<>"",CHAR(10)&INDEX('Controle de reservas'!$M$14:$M$2013,AU10),IF(OR(INDEX('Controle de reservas'!$L$14:$L$2013,AU10)="Em cobertura",INDEX('Controle de reservas'!$L$14:$L$2013,AU10)="Programado"),CHAR(10)&"SEM LOCAL",""))&IF(INDEX('Controle de reservas'!$N$14:$N$2013,AU10)<>"",CHAR(10)&"Subst.: "&INDEX('Controle de reservas'!$N$14:$N$2013,AU10),"")&IF(AND(ISNUMBER(INDEX('Controle de reservas'!$I$14:$I$2013,AU10)),INDEX('Controle de reservas'!$I$14:$I$2013,AU10)>0,INDEX('Controle de reservas'!$K$14:$K$2013,AU10)>INDEX('Controle de reservas'!$I$14:$I$2013,AU10)),CHAR(10)&"DIVERGÊNCIA DE DATAS","")&IF(INDEX('Controle de reservas'!$P$14:$P$2013,AU10)<>"OK"," !","")))) | H10: =IF(OR($AQ10=0,H$9="",H$9<$AS10,AND($AT10<>"",H$9>$AT10)),"",IF(AV10=0,"—",IF(INDEX('Controle de reservas'!$P$14:$P$2013,AV10)="DUPLICIDADE NO DIA","CONFLITO"&IF(INDEX('Controle de reservas'!$M$14:$M$2013,AV10)<>"",CHAR(10)&INDEX('Controle de reservas'!$M$14:$M$2013,AV10),"")&IF(INDEX('Controle de reservas'!$N$14:$N$2013,AV10)<>"",CHAR(10)&"Subst.: "&INDEX('Controle de reservas'!$N$14:$N$2013,AV10),"")&IF(AND(ISNUMBER(INDEX('Controle de reservas'!$I$14:$I$2013,AV10)),INDEX('Controle de reservas'!$I$14:$I$2013,AV10)>0,INDEX('Controle de reservas'!$K$14:$K$2013,AV10)>INDEX('Controle de reservas'!$I$14:$I$2013,AV10)),CHAR(10)&"DIVERGÊNCIA DE DATAS",""),IF(INDEX('Controle de reservas'!$L$14:$L$2013,AV10)="Em cobertura","COV",IF(INDEX('Controle de reservas'!$L$14:$L$2013,AV10)="Disponível","DISP",IF(INDEX('Controle de reservas'!$L$14:$L$2013,AV10)="Não utilizado","NU",IF(INDEX('Controle de reservas'!$L$14:$L$2013,AV10)="Folga","F",IF(INDEX('Controle de reservas'!$L$14:$L$2013,AV10)="Ocorrência","O",IF(INDEX('Controle de reservas'!$L$14:$L$2013,AV10)="Programado","PROG",IF(INDEX('Controle de reservas'!$L$14:$L$2013,AV10)="Disponível no posto","DP","SEM SITUAÇÃO")))))))&IF(INDEX('Controle de reservas'!$M$14:$M$2013,AV10)<>"",CHAR(10)&INDEX('Controle de reservas'!$M$14:$M$2013,AV10),IF(OR(INDEX('Controle de reservas'!$L$14:$L$2013,AV10)="Em cobertura",INDEX('Controle de reservas'!$L$14:$L$2013,AV10)="Programado"),CHAR(10)&"SEM LOCAL",""))&IF(INDEX('Controle de reservas'!$N$14:$N$2013,AV10)<>"",CHAR(10)&"Subst.: "&INDEX('Controle de reservas'!$N$14:$N$2013,AV10),"")&IF(AND(ISNUMBER(INDEX('Controle de reservas'!$I$14:$I$2013,AV10)),INDEX('Controle de reservas'!$I$14:$I$2013,AV10)>0,INDEX('Controle de reservas'!$K$14:$K$2013,AV10)>INDEX('Controle de reservas'!$I$14:$I$2013,AV10)),CHAR(10)&"DIVERGÊNCIA DE DATAS","")&IF(INDEX('Controle de reservas'!$P$14:$P$2013,AV10)<>"OK"," !","")))) | I10: =IF(OR($AQ10=0,I$9="",I$9<$AS10,AND($AT10<>"",I$9>$AT10)),"",IF(AW10=0,"—",IF(INDEX('Controle de reservas'!$P$14:$P$2013,AW10)="DUPLICIDADE NO DIA","CONFLITO"&IF(INDEX('Controle de reservas'!$M$14:$M$2013,AW10)<>"",CHAR(10)&INDEX('Controle de reservas'!$M$14:$M$2013,AW10),"")&IF(INDEX('Controle de reservas'!$N$14:$N$2013,AW10)<>"",CHAR(10)&"Subst.: "&INDEX('Controle de reservas'!$N$14:$N$2013,AW10),"")&IF(AND(ISNUMBER(INDEX('Controle de reservas'!$I$14:$I$2013,AW10)),INDEX('Controle de reservas'!$I$14:$I$2013,AW10)>0,INDEX('Controle de reservas'!$K$14:$K$2013,AW10)>INDEX('Controle de reservas'!$I$14:$I$2013,AW10)),CHAR(10)&"DIVERGÊNCIA DE DATAS",""),IF(INDEX('Controle de reservas'!$L$14:$L$2013,AW10)="Em cobertura","COV",IF(INDEX('Controle de reservas'!$L$14:$L$2013,AW10)="Disponível","DISP",IF(INDEX('Controle de reservas'!$L$14:$L$2013,AW10)="Não utilizado","NU",IF(INDEX('Controle de reservas'!$L$14:$L$2013,AW10)="Folga","F",IF(INDEX('Controle de reservas'!$L$14:$L$2013,AW10)="Ocorrência","O",IF(INDEX('Controle de reservas'!$L$14:$L$2013,AW10)="Programado","PROG",IF(INDEX('Controle de reservas'!$L$14:$L$2013,AW10)="Disponível no posto","DP","SEM SITUAÇÃO")))))))&IF(INDEX('Controle de reservas'!$M$14:$M$2013,AW10)<>"",CHAR(10)&INDEX('Controle de reservas'!$M$14:$M$2013,AW10),IF(OR(INDEX('Controle de reservas'!$L$14:$L$2013,AW10)="Em cobertura",INDEX('Controle de reservas'!$L$14:$L$2013,AW10)="Programado"),CHAR(10)&"SEM LOCAL",""))&IF(INDEX('Controle de reservas'!$N$14:$N$2013,AW10)<>"",CHAR(10)&"Subst.: "&INDEX('Controle de reservas'!$N$14:$N$2013,AW10),"")&IF(AND(ISNUMBER(INDEX('Controle de reservas'!$I$14:$I$2013,AW10)),INDEX('Controle de reservas'!$I$14:$I$2013,AW10)>0,INDEX('Controle de reservas'!$K$14:$K$2013,AW10)>INDEX('Controle de reservas'!$I$14:$I$2013,AW10)),CHAR(10)&"DIVERGÊNCIA DE DATAS","")&IF(INDEX('Controle de reservas'!$P$14:$P$2013,AW10)<>"OK"," !","")))) | J10: =IF(OR($AQ10=0,J$9="",J$9<$AS10,AND($AT10<>"",J$9>$AT10)),"",IF(AX10=0,"—",IF(INDEX('Controle de reservas'!$P$14:$P$2013,AX10)="DUPLICIDADE NO DIA","CONFLITO"&IF(INDEX('Controle de reservas'!$M$14:$M$2013,AX10)<>"",CHAR(10)&INDEX('Controle de reservas'!$M$14:$M$2013,AX10),"")&IF(INDEX('Controle de reservas'!$N$14:$N$2013,AX10)<>"",CHAR(10)&"Subst.: "&INDEX('Controle de reservas'!$N$14:$N$2013,AX10),"")&IF(AND(ISNUMBER(INDEX('Controle de reservas'!$I$14:$I$2013,AX10)),INDEX('Controle de reservas'!$I$14:$I$2013,AX10)>0,INDEX('Controle de reservas'!$K$14:$K$2013,AX10)>INDEX('Controle de reservas'!$I$14:$I$2013,AX10)),CHAR(10)&"DIVERGÊNCIA DE DATAS",""),IF(INDEX('Controle de reservas'!$L$14:$L$2013,AX10)="Em cobertura","COV",IF(INDEX('Controle de reservas'!$L$14:$L$2013,AX10)="Disponível","DISP",IF(INDEX('Controle de reservas'!$L$14:$L$2013,AX10)="Não utilizado","NU",IF(INDEX('Controle de reservas'!$L$14:$L$2013,AX10)="Folga","F",IF(INDEX('Controle de reservas'!$L$14:$L$2013,AX10)="Ocorrência","O",IF(INDEX('Controle de reservas'!$L$14:$L$2013,AX10)="Programado","PROG",IF(INDEX('Controle de reservas'!$L$14:$L$2013,AX10)="Disponível no posto","DP","SEM SITUAÇÃO")))))))&IF(INDEX('Controle de reservas'!$M$14:$M$2013,AX10)<>"",CHAR(10)&INDEX('Controle de reservas'!$M$14:$M$2013,AX10),IF(OR(INDEX('Controle de reservas'!$L$14:$L$2013,AX10)="Em cobertura",INDEX('Controle de reservas'!$L$14:$L$2013,AX10)="Programado"),CHAR(10)&"SEM LOCAL",""))&IF(INDEX('Controle de reservas'!$N$14:$N$2013,AX10)<>"",CHAR(10)&"Subst.: "&INDEX('Controle de reservas'!$N$14:$N$2013,AX10),"")&IF(AND(ISNUMBER(INDEX('Controle de reservas'!$I$14:$I$2013,AX10)),INDEX('Controle de reservas'!$I$14:$I$2013,AX10)>0,INDEX('Controle de reservas'!$K$14:$K$2013,AX10)>INDEX('Controle de reservas'!$I$14:$I$2013,AX10)),CHAR(10)&"DIVERGÊNCIA DE DATAS","")&IF(INDEX('Controle de reservas'!$P$14:$P$2013,AX10)<>"OK"," !","")))) | K10: =IF(OR($AQ10=0,K$9="",K$9<$AS10,AND($AT10<>"",K$9>$AT10)),"",IF(AY10=0,"—",IF(INDEX('Controle de reservas'!$P$14:$P$2013,AY10)="DUPLICIDADE NO DIA","CONFLITO"&IF(INDEX('Controle de reservas'!$M$14:$M$2013,AY10)<>"",CHAR(10)&INDEX('Controle de reservas'!$M$14:$M$2013,AY10),"")&IF(INDEX('Controle de reservas'!$N$14:$N$2013,AY10)<>"",CHAR(10)&"Subst.: "&INDEX('Controle de reservas'!$N$14:$N$2013,AY10),"")&IF(AND(ISNUMBER(INDEX('Controle de reservas'!$I$14:$I$2013,AY10)),INDEX('Controle de reservas'!$I$14:$I$2013,AY10)>0,INDEX('Controle de reservas'!$K$14:$K$2013,AY10)>INDEX('Controle de reservas'!$I$14:$I$2013,AY10)),CHAR(10)&"DIVERGÊNCIA DE DATAS",""),IF(INDEX('Controle de reservas'!$L$14:$L$2013,AY10)="Em cobertura","COV",IF(INDEX('Controle de reservas'!$L$14:$L$2013,AY10)="Disponível","DISP",IF(INDEX('Controle de reservas'!$L$14:$L$2013,AY10)="Não utilizado","NU",IF(INDEX('Controle de reservas'!$L$14:$L$2013,AY10)="Folga","F",IF(INDEX('Controle de reservas'!$L$14:$L$2013,AY10)="Ocorrência","O",IF(INDEX('Controle de reservas'!$L$14:$L$2013,AY10)="Programado","PROG",IF(INDEX('Controle de reservas'!$L$14:$L$2013,AY10)="Disponível no posto","DP","SEM SITUAÇÃO")))))))&IF(INDEX('Controle de reservas'!$M$14:$M$2013,AY10)<>"",CHAR(10)&INDEX('Controle de reservas'!$M$14:$M$2013,AY10),IF(OR(INDEX('Controle de reservas'!$L$14:$L$2013,AY10)="Em cobertura",INDEX('Controle de reservas'!$L$14:$L$2013,AY10)="Programado"),CHAR(10)&"SEM LOCAL",""))&IF(INDEX('Controle de reservas'!$N$14:$N$2013,AY10)<>"",CHAR(10)&"Subst.: "&INDEX('Controle de reservas'!$N$14:$N$2013,AY10),"")&IF(AND(ISNUMBER(INDEX('Controle de reservas'!$I$14:$I$2013,AY10)),INDEX('Controle de reservas'!$I$14:$I$2013,AY10)>0,INDEX('Controle de reservas'!$K$14:$K$2013,AY10)>INDEX('Controle de reservas'!$I$14:$I$2013,AY10)),CHAR(10)&"DIVERGÊNCIA DE DATAS","")&IF(INDEX('Controle de reservas'!$P$14:$P$2013,AY10)<>"OK"," !","")))) | L10: =IF(OR($AQ10=0,L$9="",L$9<$AS10,AND($AT10<>"",L$9>$AT10)),"",IF(AZ10=0,"—",IF(INDEX('Controle de reservas'!$P$14:$P$2013,AZ10)="DUPLICIDADE NO DIA","CONFLITO"&IF(INDEX('Controle de reservas'!$M$14:$M$2013,AZ10)<>"",CHAR(10)&INDEX('Controle de reservas'!$M$14:$M$2013,AZ10),"")&IF(INDEX('Controle de reservas'!$N$14:$N$2013,AZ10)<>"",CHAR(10)&"Subst.: "&INDEX('Controle de reservas'!$N$14:$N$2013,AZ10),"")&IF(AND(ISNUMBER(INDEX('Controle de reservas'!$I$14:$I$2013,AZ10)),INDEX('Controle de reservas'!$I$14:$I$2013,AZ10)>0,INDEX('Controle de reservas'!$K$14:$K$2013,AZ10)>INDEX('Controle de reservas'!$I$14:$I$2013,AZ10)),CHAR(10)&"DIVERGÊNCIA DE DATAS",""),IF(INDEX('Controle de reservas'!$L$14:$L$2013,AZ10)="Em cobertura","COV",IF(INDEX('Controle de reservas'!$L$14:$L$2013,AZ10)="Disponível","DISP",IF(INDEX('Controle de reservas'!$L$14:$L$2013,AZ10)="Não utilizado","NU",IF(INDEX('Controle de reservas'!$L$14:$L$2013,AZ10)="Folga","F",IF(INDEX('Controle de reservas'!$L$14:$L$2013,AZ10)="Ocorrência","O",IF(INDEX('Controle de reservas'!$L$14:$L$2013,AZ10)="Programado","PROG",IF(INDEX('Controle de reservas'!$L$14:$L$2013,AZ10)="Disponível no posto","DP","SEM SITUAÇÃO")))))))&IF(INDEX('Controle de reservas'!$M$14:$M$2013,AZ10)<>"",CHAR(10)&INDEX('Controle de reservas'!$M$14:$M$2013,AZ10),IF(OR(INDEX('Controle de reservas'!$L$14:$L$2013,AZ10)="Em cobertura",INDEX('Controle de reservas'!$L$14:$L$2013,AZ10)="Programado"),CHAR(10)&"SEM LOCAL",""))&IF(INDEX('Controle de reservas'!$N$14:$N$2013,AZ10)<>"",CHAR(10)&"Subst.: "&INDEX('Controle de reservas'!$N$14:$N$2013,AZ10),"")&IF(AND(ISNUMBER(INDEX('Controle de reservas'!$I$14:$I$2013,AZ10)),INDEX('Controle de reservas'!$I$14:$I$2013,AZ10)>0,INDEX('Controle de reservas'!$K$14:$K$2013,AZ10)>INDEX('Controle de reservas'!$I$14:$I$2013,AZ10)),CHAR(10)&"DIVERGÊNCIA DE DATAS","")&IF(INDEX('Controle de reservas'!$P$14:$P$2013,AZ10)<>"OK"," !","")))) | M10: =IF(OR($AQ10=0,M$9="",M$9<$AS10,AND($AT10<>"",M$9>$AT10)),"",IF(BA10=0,"—",IF(INDEX('Controle de reservas'!$P$14:$P$2013,BA10)="DUPLICIDADE NO DIA","CONFLITO"&IF(INDEX('Controle de reservas'!$M$14:$M$2013,BA10)<>"",CHAR(10)&INDEX('Controle de reservas'!$M$14:$M$2013,BA10),"")&IF(INDEX('Controle de reservas'!$N$14:$N$2013,BA10)<>"",CHAR(10)&"Subst.: "&INDEX('Controle de reservas'!$N$14:$N$2013,BA10),"")&IF(AND(ISNUMBER(INDEX('Controle de reservas'!$I$14:$I$2013,BA10)),INDEX('Controle de reservas'!$I$14:$I$2013,BA10)>0,INDEX('Controle de reservas'!$K$14:$K$2013,BA10)>INDEX('Controle de reservas'!$I$14:$I$2013,BA10)),CHAR(10)&"DIVERGÊNCIA DE DATAS",""),IF(INDEX('Controle de reservas'!$L$14:$L$2013,BA10)="Em cobertura","COV",IF(INDEX('Controle de reservas'!$L$14:$L$2013,BA10)="Disponível","DISP",IF(INDEX('Controle de reservas'!$L$14:$L$2013,BA10)="Não utilizado","NU",IF(INDEX('Controle de reservas'!$L$14:$L$2013,BA10)="Folga","F",IF(INDEX('Controle de reservas'!$L$14:$L$2013,BA10)="Ocorrência","O",IF(INDEX('Controle de reservas'!$L$14:$L$2013,BA10)="Programado","PROG",IF(INDEX('Controle de reservas'!$L$14:$L$2013,BA10)="Disponível no posto","DP","SEM SITUAÇÃO")))))))&IF(INDEX('Controle de reservas'!$M$14:$M$2013,BA10)<>"",CHAR(10)&INDEX('Controle de reservas'!$M$14:$M$2013,BA10),IF(OR(INDEX('Controle de reservas'!$L$14:$L$2013,BA10)="Em cobertura",INDEX('Controle de reservas'!$L$14:$L$2013,BA10)="Programado"),CHAR(10)&"SEM LOCAL",""))&IF(INDEX('Controle de reservas'!$N$14:$N$2013,BA10)<>"",CHAR(10)&"Subst.: "&INDEX('Controle de reservas'!$N$14:$N$2013,BA10),"")&IF(AND(ISNUMBER(INDEX('Controle de reservas'!$I$14:$I$2013,BA10)),INDEX('Controle de reservas'!$I$14:$I$2013,BA10)>0,INDEX('Controle de reservas'!$K$14:$K$2013,BA10)>INDEX('Controle de reservas'!$I$14:$I$2013,BA10)),CHAR(10)&"DIVERGÊNCIA DE DATAS","")&IF(INDEX('Controle de reservas'!$P$14:$P$2013,BA10)<>"OK"," !","")))) | N10: =IF(OR($AQ10=0,N$9="",N$9<$AS10,AND($AT10<>"",N$9>$AT10)),"",IF(BB10=0,"—",IF(INDEX('Controle de reservas'!$P$14:$P$2013,BB10)="DUPLICIDADE NO DIA","CONFLITO"&IF(INDEX('Controle de reservas'!$M$14:$M$2013,BB10)<>"",CHAR(10)&INDEX('Controle de reservas'!$M$14:$M$2013,BB10),"")&IF(INDEX('Controle de reservas'!$N$14:$N$2013,BB10)<>"",CHAR(10)&"Subst.: "&INDEX('Controle de reservas'!$N$14:$N$2013,BB10),"")&IF(AND(ISNUMBER(INDEX('Controle de reservas'!$I$14:$I$2013,BB10)),INDEX('Controle de reservas'!$I$14:$I$2013,BB10)>0,INDEX('Controle de reservas'!$K$14:$K$2013,BB10)>INDEX('Controle de reservas'!$I$14:$I$2013,BB10)),CHAR(10)&"DIVERGÊNCIA DE DATAS",""),IF(INDEX('Controle de reservas'!$L$14:$L$2013,BB10)="Em cobertura","COV",IF(INDEX('Controle de reservas'!$L$14:$L$2013,BB10)="Disponível","DISP",IF(INDEX('Controle de reservas'!$L$14:$L$2013,BB10)="Não utilizado","NU",IF(INDEX('Controle de reservas'!$L$14:$L$2013,BB10)="Folga","F",IF(INDEX('Controle de reservas'!$L$14:$L$2013,BB10)="Ocorrência","O",IF(INDEX('Controle de reservas'!$L$14:$L$2013,BB10)="Programado","PROG",IF(INDEX('Controle de reservas'!$L$14:$L$2013,BB10)="Disponível no posto","DP","SEM SITUAÇÃO")))))))&IF(INDEX('Controle de reservas'!$M$14:$M$2013,BB10)<>"",CHAR(10)&INDEX('Controle de reservas'!$M$14:$M$2013,BB10),IF(OR(INDEX('Controle de reservas'!$L$14:$L$2013,BB10)="Em cobertura",INDEX('Controle de reservas'!$L$14:$L$2013,BB10)="Programado"),CHAR(10)&"SEM LOCAL",""))&IF(INDEX('Controle de reservas'!$N$14:$N$2013,BB10)<>"",CHAR(10)&"Subst.: "&INDEX('Controle de reservas'!$N$14:$N$2013,BB10),"")&IF(AND(ISNUMBER(INDEX('Controle de reservas'!$I$14:$I$2013,BB10)),INDEX('Controle de reservas'!$I$14:$I$2013,BB10)>0,INDEX('Controle de reservas'!$K$14:$K$2013,BB10)>INDEX('Controle de reservas'!$I$14:$I$2013,BB10)),CHAR(10)&"DIVERGÊNCIA DE DATAS","")&IF(INDEX('Controle de reservas'!$P$14:$P$2013,BB10)<>"OK"," !","")))) | ... AK10: =IF(OR($AQ10=0,AK$9="",AK$9<$AS10,AND($AT10<>"",AK$9>$AT10)),"",IF(BY10=0,"—",IF(INDEX('Controle de reservas'!$P$14:$P$2013,BY10)="DUPLICIDADE NO DIA","CONFLITO"&IF(INDEX('Controle de reservas'!$M$14:$M$2013,BY10)<>"",CHAR(10)&INDEX('Controle de reservas'!$M$14:$M$2013,BY10),"")&IF(INDEX('Controle de reservas'!$N$14:$N$2013,BY10)<>"",CHAR(10)&"Subst.: "&INDEX('Controle de reservas'!$N$14:$N$2013,BY10),"")&IF(AND(ISNUMBER(INDEX('Controle de reservas'!$I$14:$I$2013,BY10)),INDEX('Controle de reservas'!$I$14:$I$2013,BY10)>0,INDEX('Controle de reservas'!$K$14:$K$2013,BY10)>INDEX('Controle de reservas'!$I$14:$I$2013,BY10)),CHAR(10)&"DIVERGÊNCIA DE DATAS",""),IF(INDEX('Controle de reservas'!$L$14:$L$2013,BY10)="Em cobertura","COV",IF(INDEX('Controle de reservas'!$L$14:$L$2013,BY10)="Disponível","DISP",IF(INDEX('Controle de reservas'!$L$14:$L$2013,BY10)="Não utilizado","NU",IF(INDEX('Controle de reservas'!$L$14:$L$2013,BY10)="Folga","F",IF(INDEX('Controle de reservas'!$L$14:$L$2013,BY10)="Ocorrência","O",IF(INDEX('Controle de reservas'!$L$14:$L$2013,BY10)="Programado","PROG",IF(INDEX('Controle de reservas'!$L$14:$L$2013,BY10)="Disponível no posto","DP","SEM SITUAÇÃO")))))))&IF(INDEX('Controle de reservas'!$M$14:$M$2013,BY10)<>"",CHAR(10)&INDEX('Controle de reservas'!$M$14:$M$2013,BY10),IF(OR(INDEX('Controle de reservas'!$L$14:$L$2013,BY10)="Em cobertura",INDEX('Controle de reservas'!$L$14:$L$2013,BY10)="Programado"),CHAR(10)&"SEM LOCAL",""))&IF(INDEX('Controle de reservas'!$N$14:$N$2013,BY10)<>"",CHAR(10)&"Subst.: "&INDEX('Controle de reservas'!$N$14:$N$2013,BY10),"")&IF(AND(ISNUMBER(INDEX('Controle de reservas'!$I$14:$I$2013,BY10)),INDEX('Controle de reservas'!$I$14:$I$2013,BY10)>0,INDEX('Controle de reservas'!$K$14:$K$2013,BY10)>INDEX('Controle de reservas'!$I$14:$I$2013,BY10)),CHAR(10)&"DIVERGÊNCIA DE DATAS","")&IF(INDEX('Controle de reservas'!$P$14:$P$2013,BY10)<>"OK"," !","")))) | AL10: =IF($AQ10=0,"",COUNTIF(G10:AK10,"COV*")-COUNTIF(G10:AK10,"COV* !")) | AM10: =IF($AQ10=0,"",COUNTIF(G10:AK10,"DISP*")-COUNTIF(G10:AK10,"DISP* !")) | AN10: =IF($AQ10=0,"",COUNTIF(G10:AK10,"NU*")-COUNTIF(G10:AK10,"NU* !")) | AO10: =IF($AQ10=0,"",SUMPRODUCT(--(G10:AK10="—"),--($G$9:$AK$9<>""),--($G$9:$AK$9<=TODAY()))) | AP10: =IF($AQ10=0,"",INDEX('Controle de reservas'!$O$14:$O$2013,$AQ10)) | AQ10: =IFERROR(MATCH(ROW()-9,'Controle de reservas'!$S$14:$S$2013,0),0) | AR10: =IF($AQ10=0,"",INDEX('Controle de reservas'!$Q$14:$Q$2013,$AQ10)) | AS10: =IF($AQ10=0,"",INDEX('Controle de reservas'!$H$14:$H$2013,$AQ10)) | AT10: =IF($AQ10=0,"",IF(INDEX('Controle de reservas'!$J$14:$J$2013,$AQ10)=0,"",INDEX('Controle de reservas'!$J$14:$J$2013,$AQ10))) | AU10: =IF(OR($AQ10=0,G$9=""),0,IFERROR(MATCH($AR10&"|"&TEXT(G$9,"yyyymmdd"),'Controle de reservas'!$T$14:$T$2013,0),0)) | AV10: =IF(OR($AQ10=0,H$9=""),0,IFERROR(MATCH($AR10&"|"&TEXT(H$9,"yyyymmdd"),'Controle de reservas'!$T$14:$T$2013,0),0)) | AW10: =IF(OR($AQ10=0,I$9=""),0,IFERROR(MATCH($AR10&"|"&TEXT(I$9,"yyyymmdd"),'Controle de reservas'!$T$14:$T$2013,0),0)) | AX10: =IF(OR($AQ10=0,J$9=""),0,IFERROR(MATCH($AR10&"|"&TEXT(J$9,"yyyymmdd"),'Controle de reservas'!$T$14:$T$2013,0),0)) | AY10: =IF(OR($AQ10=0,K$9=""),0,IFERROR(MATCH($AR10&"|"&TEXT(K$9,"yyyymmdd"),'Controle de reservas'!$T$14:$T$2013,0),0)) | AZ10: =IF(OR($AQ10=0,L$9=""),0,IFERROR(MATCH($AR10&"|"&TEXT(L$9,"yyyymmdd"),'Controle de reservas'!$T$14:$T$2013,0),0)) | BA10: =IF(OR($AQ10=0,M$9=""),0,IFERROR(MATCH($AR10&"|"&TEXT(M$9,"yyyymmdd"),'Controle de reservas'!$T$14:$T$2013,0),0)) | BB10: =IF(OR($AQ10=0,N$9=""),0,IFERROR(MATCH($AR10&"|"&TEXT(N$9,"yyyymmdd"),'Controle de reservas'!$T$14:$T$2013,0),0)) | ... BY10: =IF(OR($AQ10=0,AK$9=""),0,IFERROR(MATCH($AR10&"|"&TEXT(AK$9,"yyyymmdd"),'Controle de reservas'!$T$14:$T$2013,0),0))
